<?xml version="1.0" encoding="utf-8"?>
<!-- This URDF was automatically created by SolidWorks to URDF Exporter! Originally created by Stephen Brawner (brawner@gmail.com) 
     Commit Version: 1.6.0-4-g7f85cfe  Build Version: 1.6.7995.38578
     For more information, please see http://wiki.ros.org/sw_urdf_exporter -->
<robot
  name="par6_ssg48_urdf">
  <link
    name="base_link">
    <inertial>
      <origin
        xyz="-0.032918 -3.976E-09 0.031401"
        rpy="0 0 0" />
      <mass
        value="0.553" />
      <inertia
        ixx="0.0011895"
        ixy="-3.5359E-12"
        ixz="-5.9492E-05"
        iyy="0.0023816"
        iyz="-6.1682E-11"
        izz="0.0028249" />
    </inertial>
    <visual>
      <origin
        xyz="0 0 0"
        rpy="0 0 0" />
      <geometry>
        <mesh
          filename="package://par6_ssg48_gripper/meshes/base_link.STL" />
      </geometry>
      <material
        name="">
        <color
          rgba="0.792156862745098 0.819607843137255 0.933333333333333 1" />
      </material>
    </visual>
    <collision>
      <origin
        xyz="0 0 0"
        rpy="0 0 0" />
      <geometry>
        <mesh
          filename="package://par6_ssg48_gripper/meshes/base_link.STL" />
      </geometry>
    </collision>
  </link>
  <link
    name="shoulder">
    <inertial>
      <origin
        xyz="0.0065681 0.029094 0.099551"
        rpy="0 0 0" />
      <mass
        value="1.993" />
      <inertia
        ixx="0.0010066"
        ixy="-6.2658E-05"
        ixz="-5.9491E-05"
        iyy="0.00054695"
        iyz="-0.00013311"
        izz="0.0011908" />
    </inertial>
    <visual>
      <origin
        xyz="0 0 0"
        rpy="0 0 0" />
      <geometry>
        <mesh
          filename="package://par6_ssg48_gripper/meshes/shoulder.STL" />
      </geometry>
      <material
        name="">
        <color
          rgba="0.792156862745098 0.819607843137255 0.933333333333333 1" />
      </material>
    </visual>
    <collision>
      <origin
        xyz="0 0 0"
        rpy="0 0 0" />
      <geometry>
        <mesh
          filename="package://par6_ssg48_gripper/meshes/shoulder.STL" />
      </geometry>
    </collision>
  </link>
  <joint
    name="shoulder_JOINT"
    type="revolute">
    <origin
      xyz="0 0 0"
      rpy="0 0 0" />
    <parent
      link="base_link" />
    <child
      link="shoulder" />
    <axis
      xyz="0 0 -1" />
    <limit
      lower="0"
      upper="0"
      effort="0"
      velocity="0" />
  </joint>
  <link
    name="upper_arm">
    <inertial>
      <origin
        xyz="-0.0085493 -0.071342 0.041639"
        rpy="0 0 0" />
      <mass
        value="1.332" />
      <inertia
        ixx="0.001614"
        ixy="-2.3762E-05"
        ixz="-1.2377E-05"
        iyy="0.0002833"
        iyz="-0.00013464"
        izz="0.0016392" />
    </inertial>
    <visual>
      <origin
        xyz="0 0 0"
        rpy="0 0 0" />
      <geometry>
        <mesh
          filename="package://par6_ssg48_gripper/meshes/upper_arm.STL" />
      </geometry>
      <material
        name="">
        <color
          rgba="0.792156862745098 0.819607843137255 0.933333333333333 1" />
      </material>
    </visual>
    <collision>
      <origin
        xyz="0 0 0"
        rpy="0 0 0" />
      <geometry>
        <mesh
          filename="package://par6_ssg48_gripper/meshes/upper_arm.STL" />
      </geometry>
    </collision>
  </link>
  <joint
    name="upper_arm_JOINT"
    type="revolute">
    <origin
      xyz="0.023421 0 0.1105"
      rpy="-1.5708 0 0" />
    <parent
      link="shoulder" />
    <child
      link="upper_arm" />
    <axis
      xyz="0 0 1" />
    <limit
      lower="-0.9"
      upper="0.9"
      effort="0"
      velocity="0" />
  </joint>
  <link
    name="elbow">
    <inertial>
      <origin
        xyz="0.015551 -0.019113 -0.0015332"
        rpy="0 0 0" />
      <mass
        value="0.681" />
      <inertia
        ixx="0.00057828"
        ixy="0.00011651"
        ixz="-1.1996E-05"
        iyy="0.00056701"
        iyz="1.5581E-05"
        izz="0.00081586" />
    </inertial>
    <visual>
      <origin
        xyz="0 0 0"
        rpy="0 0 0" />
      <geometry>
        <mesh
          filename="package://par6_ssg48_gripper/meshes/elbow.STL" />
      </geometry>
      <material
        name="">
        <color
          rgba="0.792156862745098 0.819607843137255 0.933333333333333 1" />
      </material>
    </visual>
    <collision>
      <origin
        xyz="0 0 0"
        rpy="0 0 0" />
      <geometry>
        <mesh
          filename="package://par6_ssg48_gripper/meshes/elbow.STL" />
      </geometry>
    </collision>
  </link>
  <joint
    name="elbow_JOINT"
    type="revolute">
    <origin
      xyz="0 -0.18 0"
      rpy="3.1416 0 -1.5708" />
    <parent
      link="upper_arm" />
    <child
      link="elbow" />
    <axis
      xyz="0 0 -1" />
    <limit
      lower="0"
      upper="0"
      effort="0"
      velocity="0" />
  </joint>
  <link
    name="lower_arm">
    <inertial>
      <origin
        xyz="0.00052734 -0.010166 -0.092593"
        rpy="0 0 0" />
      <mass
        value="0.579" />
      <inertia
        ixx="0.00038381"
        ixy="-5.7178E-06"
        ixz="-1.1344E-06"
        iyy="0.00032461"
        iyz="-6.4819E-05"
        izz="0.00025249" />
    </inertial>
    <visual>
      <origin
        xyz="0 0 0"
        rpy="0 0 0" />
      <geometry>
        <mesh
          filename="package://par6_ssg48_gripper/meshes/lower_arm.STL" />
      </geometry>
      <material
        name="">
        <color
          rgba="0.792156862745098 0.819607843137255 0.933333333333333 1" />
      </material>
    </visual>
    <collision>
      <origin
        xyz="0 0 0"
        rpy="0 0 0" />
      <geometry>
        <mesh
          filename="package://par6_ssg48_gripper/meshes/lower_arm.STL" />
      </geometry>
    </collision>
  </link>
  <joint
    name="lower_arm_JOINT"
    type="revolute">
    <origin
      xyz="0.0435 0 0"
      rpy="1.5708 0 -3.1416" />
    <parent
      link="elbow" />
    <child
      link="lower_arm" />
    <axis
      xyz="0 0 -1" />
    <limit
      lower="0"
      upper="0"
      effort="0"
      velocity="0" />
  </joint>
  <link
    name="wrist">
    <inertial>
      <origin
        xyz="-1.5461E-06 -0.0031485 0.00019393"
        rpy="0 0 0" />
      <mass
        value="0.523" />
      <inertia
        ixx="0.00018083"
        ixy="-4.6339E-10"
        ixz="-6.7928E-09"
        iyy="0.00010621"
        iyz="2.8796E-06"
        izz="0.0001756" />
    </inertial>
    <visual>
      <origin
        xyz="0 0 0"
        rpy="0 0 0" />
      <geometry>
        <mesh
          filename="package://par6_ssg48_gripper/meshes/wrist.STL" />
      </geometry>
      <material
        name="">
        <color
          rgba="0.792156862745098 0.819607843137255 0.933333333333333 1" />
      </material>
    </visual>
    <collision>
      <origin
        xyz="0 0 0"
        rpy="0 0 0" />
      <geometry>
        <mesh
          filename="package://par6_ssg48_gripper/meshes/wrist.STL" />
      </geometry>
    </collision>
  </link>
  <joint
    name="wrist_JOINT"
    type="revolute">
    <origin
      xyz="0 0 -0.177"
      rpy="-1.5708 0 0" />
    <parent
      link="lower_arm" />
    <child
      link="wrist" />
    <axis
      xyz="0 0 1" />
    <limit
      lower="0"
      upper="0"
      effort="0"
      velocity="0" />
  </joint>
  <link
    name="gripper">
    <inertial>
      <origin
        xyz="-6.7987E-05 0.0001694 -0.077391"
        rpy="0 0 0" />
      <mass
        value="0.374" />
      <inertia
        ixx="0.00012751"
        ixy="-1.7736E-07"
        ixz="-2.8206E-06"
        iyy="5.8635E-05"
        iyz="-5.29E-07"
        izz="0.00014769" />
    </inertial>
    <visual>
      <origin
        xyz="0 0 0"
        rpy="0 0 0" />
      <geometry>
        <mesh
          filename="package://par6_ssg48_gripper/meshes/gripper.STL" />
      </geometry>
      <material
        name="">
        <color
          rgba="0.792156862745098 0.819607843137255 0.933333333333333 1" />
      </material>
    </visual>
    <collision>
      <origin
        xyz="0 0 0"
        rpy="0 0 0" />
      <geometry>
        <mesh
          filename="package://par6_ssg48_gripper/meshes/gripper.STL" />
      </geometry>
    </collision>
  </link>
  <joint
    name="gripper_JOINT"
    type="revolute">
    <origin
      xyz="0 0 0"
      rpy="1.5708 0 0" />
    <parent
      link="wrist" />
    <child
      link="gripper" />
    <axis
      xyz="0 0 -1" />
    <limit
      lower="0"
      upper="0"
      effort="0"
      velocity="0" />
  </joint>
  <link
    name="jaw1">
    <inertial>
      <origin
        xyz="0.0033269 0.029197 -0.0097237"
        rpy="0 0 0" />
      <mass
        value="0.02" />
      <inertia
        ixx="3.7875E-06"
        ixy="6.5971E-07"
        ixz="3.113E-07"
        iyy="1.5397E-06"
        iyz="-6.1777E-07"
        izz="4.4716E-06" />
    </inertial>
    <visual>
      <origin
        xyz="0 0 0"
        rpy="0 0 0" />
      <geometry>
        <mesh
          filename="package://par6_ssg48_gripper/meshes/jaw1.STL" />
      </geometry>
      <material
        name="">
        <color
          rgba="0.29804 0.29804 0.29804 1" />
      </material>
    </visual>
    <collision>
      <origin
        xyz="0 0 0"
        rpy="0 0 0" />
      <geometry>
        <mesh
          filename="package://par6_ssg48_gripper/meshes/jaw1.STL" />
      </geometry>
    </collision>
  </link>
  <joint
    name="jaw1_JOINT"
    type="prismatic">
    <origin
      xyz="0 0 -0.11745"
      rpy="-3.1416 0 -3.1416" />
    <parent
      link="gripper" />
    <child
      link="jaw1" />
    <axis
      xyz="0 -1 0" />
    <limit
      lower="0"
      upper="0"
      effort="0"
      velocity="0" />
  </joint>
  <link
    name="jaw2">
    <inertial>
      <origin
        xyz="-0.0033269 -0.029197 -0.0097237"
        rpy="0 0 0" />
      <mass
        value="0.02" />
      <inertia
        ixx="3.7875E-06"
        ixy="6.5971E-07"
        ixz="-3.113E-07"
        iyy="1.5397E-06"
        iyz="6.1777E-07"
        izz="4.4716E-06" />
    </inertial>
    <visual>
      <origin
        xyz="0 0 0"
        rpy="0 0 0" />
      <geometry>
        <mesh
          filename="package://par6_ssg48_gripper/meshes/jaw2.STL" />
      </geometry>
      <material
        name="">
        <color
          rgba="0.29804 0.29804 0.29804 1" />
      </material>
    </visual>
    <collision>
      <origin
        xyz="0 0 0"
        rpy="0 0 0" />
      <geometry>
        <mesh
          filename="package://par6_ssg48_gripper/meshes/jaw2.STL" />
      </geometry>
    </collision>
  </link>
  <joint
    name="jaw2_JOINT" type="prismatic">
    <mimic joint="jaw1_JOINT" multiplier="-1" offset="0"/>
    <origin
      xyz="0 0 -0.11745"
      rpy="-3.1416 0 -3.1416" />
    <parent
      link="gripper" />
    <child
      link="jaw2" />
    <axis
      xyz="0 -1 0" />
    <limit
      lower="0"
      upper="0"
      effort="0"
      velocity="0" />
  </joint>

  <link name="tcp">
    <visual>
      <origin xyz="0 0 0" rpy="0 0 0"/>
      <geometry>
        <sphere radius="0.003"/>
      </geometry>
      <material name="red">
        <color rgba="1 0 0 1"/>
      </material>
    </visual>
  </link>

  <joint name="tcp_fixed_joint" type="fixed">
    <parent link="gripper"/>
    <child link="tcp"/>
    <!-- Adjust this to match your real grasp center -->
    <origin xyz="0 0 -0.16" rpy="0 0 0"/>
  </joint>



<transmission name="gripper_transmission">
  <type>transmission_interface/SimpleTransmission</type>
  <joint name="gripper_JOINT">
    <hardwareInterface>PositionJointInterface</hardwareInterface>
  </joint>
  <actuator name="gripper_motor">
    <hardwareInterface>PositionJointInterface</hardwareInterface>
    <mechanicalReduction>1</mechanicalReduction>
  </actuator>
</transmission>

<transmission name="jaw_transmission">
  <type>transmission_interface/SimpleTransmission</type>
  <joint name="jaw1_JOINT">
    <hardwareInterface>PositionJointInterface</hardwareInterface>
  </joint>
  <actuator name="jaw_motor">
    <hardwareInterface>PositionJointInterface</hardwareInterface>
    <mechanicalReduction>1</mechanicalReduction>
  </actuator>
</transmission>



</robot>